Workbook

Sheet Summary
A1: Street names add-on: renamed streets for review
A2: Prepared 19 October 2026 from OpenStreetMap and official municipal announcements.
A4: How to review
A5: • On the Streets tab, fill in the yellow 'Founder decision' column with Keep, Drop or Unsure (pick from the list).
A6: • 'Suggested' is Claude's first sort: Keep, Add (announced but missing from the map data), Check (confirm first), Drop.
A7: • 'Open map' shows where the street is, so you can see the street's current name on the map.
A8: • Example: Durban | West Street | Doctor Pixley Kaseme Street | Suggested Keep | Founder decision Keep.
A9: • The table below updates as decisions are filled in.
A11: By area
A12: Area | B12: Keep | C12: Add | D12: Check | E12: Drop | F12: Founders: Keep | G12: Not reviewed
A13: Durban (eThekwini) | B13: =COUNTIFS(Streets!$A$2:$A$255,$A13,Streets!$E$2:$E$255,"Keep") -> 64 | C13: =COUNTIFS(Streets!$A$2:$A$255,$A13,Streets!$E$2:$E$255,"Add") -> 0 | D13: =COUNTIFS(Streets!$A$2:$A$255,$A13,Streets!$E$2:$E$255,"Check") -> 2 | E13: =COUNTIFS(Streets!$A$2:$A$255,$A13,Streets!$E$2:$E$255,"Drop") -> 6 | F13: =COUNTIFS(Streets!$A$2:$A$255,$A13,Streets!$F$2:$F$255,"Keep") -> 0 | G13: =COUNTIFS(Streets!$A$2:$A$255,$A13,Streets!$F$2:$F$255,"") -> 72
A14: Pretoria (Tshwane) | B14: =COUNTIFS(Streets!$A$2:$A$255,$A14,Streets!$E$2:$E$255,"Keep") -> 29 | C14: =COUNTIFS(Streets!$A$2:$A$255,$A14,Streets!$E$2:$E$255,"Add") -> 2 | D14: =COUNTIFS(Streets!$A$2:$A$255,$A14,Streets!$E$2:$E$255,"Check") -> 0 | E14: =COUNTIFS(Streets!$A$2:$A$255,$A14,Streets!$E$2:$E$255,"Drop") -> 8 | F14: =COUNTIFS(Streets!$A$2:$A$255,$A14,Streets!$F$2:$F$255,"Keep") -> 0 | G14: =COUNTIFS(Streets!$A$2:$A$255,$A14,Streets!$F$2:$F$255,"") -> 39
A15: Ekurhuleni (East Rand) | B15: =COUNTIFS(Streets!$A$2:$A$255,$A15,Streets!$E$2:$E$255,"Keep") -> 1 | C15: =COUNTIFS(Streets!$A$2:$A$255,$A15,Streets!$E$2:$E$255,"Add") -> 29 | D15: =COUNTIFS(Streets!$A$2:$A$255,$A15,Streets!$E$2:$E$255,"Check") -> 0 | E15: =COUNTIFS(Streets!$A$2:$A$255,$A15,Streets!$E$2:$E$255,"Drop") -> 0 | F15: =COUNTIFS(Streets!$A$2:$A$255,$A15,Streets!$F$2:$F$255,"Keep") -> 0 | G15: =COUNTIFS(Streets!$A$2:$A$255,$A15,Streets!$F$2:$F$255,"") -> 30
A16: Pietermaritzburg (Msunduzi) | B16: =COUNTIFS(Streets!$A$2:$A$255,$A16,Streets!$E$2:$E$255,"Keep") -> 18 | C16: =COUNTIFS(Streets!$A$2:$A$255,$A16,Streets!$E$2:$E$255,"Add") -> 0 | D16: =COUNTIFS(Streets!$A$2:$A$255,$A16,Streets!$E$2:$E$255,"Check") -> 1 | E16: =COUNTIFS(Streets!$A$2:$A$255,$A16,Streets!$E$2:$E$255,"Drop") -> 3 | F16: =COUNTIFS(Streets!$A$2:$A$255,$A16,Streets!$F$2:$F$255,"Keep") -> 0 | G16: =COUNTIFS(Streets!$A$2:$A$255,$A16,Streets!$F$2:$F$255,"") -> 22
A17: Johannesburg | B17: =COUNTIFS(Streets!$A$2:$A$255,$A17,Streets!$E$2:$E$255,"Keep") -> 9 | C17: =COUNTIFS(Streets!$A$2:$A$255,$A17,Streets!$E$2:$E$255,"Add") -> 6 | D17: =COUNTIFS(Streets!$A$2:$A$255,$A17,Streets!$E$2:$E$255,"Check") -> 0 | E17: =COUNTIFS(Streets!$A$2:$A$255,$A17,Streets!$E$2:$E$255,"Drop") -> 5 | F17: =COUNTIFS(Streets!$A$2:$A$255,$A17,Streets!$F$2:$F$255,"Keep") -> 0 | G17: =COUNTIFS(Streets!$A$2:$A$255,$A17,Streets!$F$2:$F$255,"") -> 20
A18: Cape Town | B18: =COUNTIFS(Streets!$A$2:$A$255,$A18,Streets!$E$2:$E$255,"Keep") -> 14 | C18: =COUNTIFS(Streets!$A$2:$A$255,$A18,Streets!$E$2:$E$255,"Add") -> 0 | D18: =COUNTIFS(Streets!$A$2:$A$255,$A18,Streets!$E$2:$E$255,"Check") -> 2 | E18: =COUNTIFS(Streets!$A$2:$A$255,$A18,Streets!$E$2:$E$255,"Drop") -> 8 | F18: =COUNTIFS(Streets!$A$2:$A$255,$A18,Streets!$F$2:$F$255,"Keep") -> 0 | G18: =COUNTIFS(Streets!$A$2:$A$255,$A18,Streets!$F$2:$F$255,"") -> 24
A19: Potchefstroom | B19: =COUNTIFS(Streets!$A$2:$A$255,$A19,Streets!$E$2:$E$255,"Keep") -> 11 | C19: =COUNTIFS(Streets!$A$2:$A$255,$A19,Streets!$E$2:$E$255,"Add") -> 0 | D19: =COUNTIFS(Streets!$A$2:$A$255,$A19,Streets!$E$2:$E$255,"Check") -> 3 | E19: =COUNTIFS(Streets!$A$2:$A$255,$A19,Streets!$E$2:$E$255,"Drop") -> 0 | F19: =COUNTIFS(Streets!$A$2:$A$255,$A19,Streets!$F$2:$F$255,"Keep") -> 0 | G19: =COUNTIFS(Streets!$A$2:$A$255,$A19,Streets!$F$2:$F$255,"") -> 14
A20: Gqeberha (Nelson Mandela Bay) | B20: =COUNTIFS(Streets!$A$2:$A$255,$A20,Streets!$E$2:$E$255,"Keep") -> 3 | C20: =COUNTIFS(Streets!$A$2:$A$255,$A20,Streets!$E$2:$E$255,"Add") -> 0 | D20: =COUNTIFS(Streets!$A$2:$A$255,$A20,Streets!$E$2:$E$255,"Check") -> 0 | E20: =COUNTIFS(Streets!$A$2:$A$255,$A20,Streets!$E$2:$E$255,"Drop") -> 3 | F20: =COUNTIFS(Streets!$A$2:$A$255,$A20,Streets!$F$2:$F$255,"Keep") -> 0 | G20: =COUNTIFS(Streets!$A$2:$A$255,$A20,Streets!$F$2:$F$255,"") -> 6
A21: Modimolle | B21: =COUNTIFS(Streets!$A$2:$A$255,$A21,Streets!$E$2:$E$255,"Keep") -> 3 | C21: =COUNTIFS(Streets!$A$2:$A$255,$A21,Streets!$E$2:$E$255,"Add") -> 0 | D21: =COUNTIFS(Streets!$A$2:$A$255,$A21,Streets!$E$2:$E$255,"Check") -> 0 | E21: =COUNTIFS(Streets!$A$2:$A$255,$A21,Streets!$E$2:$E$255,"Drop") -> 0 | F21: =COUNTIFS(Streets!$A$2:$A$255,$A21,Streets!$F$2:$F$255,"Keep") -> 0 | G21: =COUNTIFS(Streets!$A$2:$A$255,$A21,Streets!$F$2:$F$255,"") -> 3
A22: KwaDukuza | B22: =COUNTIFS(Streets!$A$2:$A$255,$A22,Streets!$E$2:$E$255,"Keep") -> 2 | C22: =COUNTIFS(Streets!$A$2:$A$255,$A22,Streets!$E$2:$E$255,"Add") -> 0 | D22: =COUNTIFS(Streets!$A$2:$A$255,$A22,Streets!$E$2:$E$255,"Check") -> 0 | E22: =COUNTIFS(Streets!$A$2:$A$255,$A22,Streets!$E$2:$E$255,"Drop") -> 0 | F22: =COUNTIFS(Streets!$A$2:$A$255,$A22,Streets!$F$2:$F$255,"Keep") -> 0 | G22: =COUNTIFS(Streets!$A$2:$A$255,$A22,Streets!$F$2:$F$255,"") -> 2
A23: Bethal | B23: =COUNTIFS(Streets!$A$2:$A$255,$A23,Streets!$E$2:$E$255,"Keep") -> 1 | C23: =COUNTIFS(Streets!$A$2:$A$255,$A23,Streets!$E$2:$E$255,"Add") -> 0 | D23: =COUNTIFS(Streets!$A$2:$A$255,$A23,Streets!$E$2:$E$255,"Check") -> 0 | E23: =COUNTIFS(Streets!$A$2:$A$255,$A23,Streets!$E$2:$E$255,"Drop") -> 0 | F23: =COUNTIFS(Streets!$A$2:$A$255,$A23,Streets!$F$2:$F$255,"Keep") -> 0 | G23: =COUNTIFS(Streets!$A$2:$A$255,$A23,Streets!$F$2:$F$255,"") -> 1
A24: Bloemfontein (Mangaung) | B24: =COUNTIFS(Streets!$A$2:$A$255,$A24,Streets!$E$2:$E$255,"Keep") -> 1 | C24: =COUNTIFS(Streets!$A$2:$A$255,$A24,Streets!$E$2:$E$255,"Add") -> 0 | D24: =COUNTIFS(Streets!$A$2:$A$255,$A24,Streets!$E$2:$E$255,"Check") -> 1 | E24: =COUNTIFS(Streets!$A$2:$A$255,$A24,Streets!$E$2:$E$255,"Drop") -> 2 | F24: =COUNTIFS(Streets!$A$2:$A$255,$A24,Streets!$F$2:$F$255,"Keep") -> 0 | G24: =COUNTIFS(Streets!$A$2:$A$255,$A24,Streets!$F$2:$F$255,"") -> 4
... A39: Zastron | B39: =COUNTIFS(Streets!$A$2:$A$255,$A39,Streets!$E$2:$E$255,"Keep") -> 0 | C39: =COUNTIFS(Streets!$A$2:$A$255,$A39,Streets!$E$2:$E$255,"Add") -> 0 | D39: =COUNTIFS(Streets!$A$2:$A$255,$A39,Streets!$E$2:$E$255,"Check") -> 0 | E39: =COUNTIFS(Streets!$A$2:$A$255,$A39,Streets!$E$2:$E$255,"Drop") -> 1 | F39: =COUNTIFS(Streets!$A$2:$A$255,$A39,Streets!$F$2:$F$255,"Keep") -> 0 | G39: =COUNTIFS(Streets!$A$2:$A$255,$A39,Streets!$F$2:$F$255,"") -> 1
A40: Total | B40: =SUM(B13:B39) -> 160 | C40: =SUM(C13:C39) -> 37 | D40: =SUM(D13:D39) -> 15 | E40: =SUM(E13:E39) -> 42 | F40: =SUM(F13:F39) -> 0 | G40: =SUM(G13:G39) -> 254
A42: What the research found
A43: • OpenStreetMap has 5,087 South African street pieces tagged with an old name. Merged, they give 217 old/new pairs; 160 are clear renames.
A44: • Durban (64), Pretoria (29), Pietermaritzburg (18), Cape Town (14) and Potchefstroom (11) have enough to make the add-on worthwhile.
A45: • Pretoria matches the city's official 2012 list well: 26 of 28 lines are in the map data; the other 2 are added by hand.
A46: • Johannesburg's 2014-15 inner-city renames (Bree, Jeppe, President, Noord, Sauer) are missing from the map data and are added by hand.
A47: • Ekurhuleni's 44 renames (approved 2019) are almost all missing; 29 with a clear old street name are added by hand. Their positions must be set by hand.
A48: • In 2011 a court reversed 9 of Durban's first-phase renames. The map data follows the current signs, but this is worth a check.
A49: • Polokwane, Mbombela and most small towns: no street renames found (they were renamed as towns only).
A50: • Map data © OpenStreetMap contributors (ODbL): the app must credit OpenStreetMap wherever these street names appear.

Sheet Streets
A1: Area | B1: Town / suburb | C1: Old name | D1: New name | E1: Suggested | F1: Founder decision | G1: Notes | H1: Source | I1: Latitude | J1: Longitude | K1: Map segments | L1: Road type | M1: See on map
A2: Bethal | B2: Bethal | C2: Church Street | D2: Jabulani Selepe Street | E2: Keep | H2: OpenStreetMap | I2: -26.45266 | J2: 29.46687 | K2: 5 | L2: tertiary | M2: Open map
A3: Bloemfontein (Mangaung) | B3: Bloemfontein | C3: Andries Pretorius Street | D3: Raymond Mhlaba Street | E3: Keep | H3: OpenStreetMap | I3: -29.1052 | J3: 26.23482 | K3: 17 | L3: primary | M3: Open map
A4: Bloemfontein (Mangaung) | B4: Bloemfontein | C4: Haldon Road | D4: Walter Sisulu Road | E4: Check | G4: Confirm with Mangaung | H4: OpenStreetMap | I4: -29.1234 | J4: 26.19797 | K4: 34 | L4: trunk | M4: Open map
A5: Bloemfontein (Mangaung) | B5: Bloemfontein | C5: Haldon Road | D5: Bell Street | E5: Drop | G5: Mapping detail: only a short joining segment | H5: OpenStreetMap | I5: -29.12547 | J5: 26.18381 | K5: 1 | L5: residential | M5: Open map
A6: Bloemfontein (Mangaung) | B6: Bloemfontein | C6: Pasteur Drive | D6: Van Rippen Crescent | E6: Drop | G6: Small local change | H6: OpenStreetMap | I6: -29.13524 | J6: 26.18792 | K6: 3 | L6: residential | M6: Open map
A7: Cape Town | B7: Cape Town | C7: Oswald Pirow Street | D7: Christiaan Barnard Street | E7: Keep | H7: OpenStreetMap | I7: -33.9211 | J7: 18.43371 | K7: 25 | L7: secondary | M7: Open map
A8: Cape Town | B8: Cape Town | C8: Table Bay Boulevard | D8: F.W. de Klerk Boulevard | E8: Keep | H8: OpenStreetMap | I8: -33.92133 | J8: 18.45198 | K8: 42 | L8: motorway | M8: Open map
A9: Cape Town | B9: Lansdowne | C9: Lansdowne Road | D9: Govan Mbeki Road | E9: Keep | H9: OpenStreetMap | I9: -34.00239 | J9: 18.51792 | K9: 150 | L9: secondary | M9: Open map
A10: Cape Town | B10: Cape Town | C10: Keizersgracht | D10: Hanover Street | E10: Keep | G10: Also mapped as: Keizersgracht Road | H10: OpenStreetMap | I10: -33.93266 | J10: 18.43728 | K10: 80 | L10: tertiary | M10: Open map
A11: Cape Town | B11: Cape Town | C11: Western Boulevard | D11: Helen Suzman Boulevard | E11: Keep | H11: OpenStreetMap | I11: -33.90727 | J11: 18.41042 | K11: 46 | L11: primary | M11: Open map
A12: Cape Town | B12: Claremont | C12: Lansdowne Road | D12: Imam Haron Road | E12: Keep | H12: OpenStreetMap | I12: -33.98306 | J12: 18.4685 | K12: 42 | L12: primary | M12: Open map
A13: Cape Town | B13: Athlone | C13: Vanguard Drive | D13: Jakes Gerwel Drive | E13: Keep | H13: OpenStreetMap | I13: -33.95529 | J13: 18.54096 | K13: 232 | L13: trunk | M13: Open map
A14: Cape Town | B14: Kuils River | C14: Lansdowne Road | D14: Japhta K. Masemola Road | E14: Keep | H14: OpenStreetMap | I14: -34.00893 | J14: 18.63592 | K14: 76 | L14: secondary | M14: Open map
A15: Cape Town | B15: Athlone | C15: Washington Drive | D15: King Langalibalele Drive | E15: Keep | H15: OpenStreetMap | I15: -33.94555 | J15: 18.53768 | K15: 19 | L15: tertiary | M15: Open map
A16: Cape Town | B16: Cape Town | C16: Eastern Boulevard | D16: Nelson Mandela Boulevard | E16: Keep | H16: OpenStreetMap | I16: -33.9189 | J16: 18.4332 | K16: 59 | L16: motorway | M16: Open map
A17: Cape Town | B17: Cape Town | C17: De Waal Drive | D17: Philip Kgosana Drive | E17: Keep | H17: OpenStreetMap | I17: -33.93877 | J17: 18.44395 | K17: 17 | L17: primary | M17: Open map
A18: Cape Town | B18: Athlone | C18: Modderdam Road | D18: Robert Sobukwe Road | E18: Keep | G18: Also mapped as: Modderdam East-West Road | H18: OpenStreetMap | I18: -33.95853 | J18: 18.55875 | K18: 78 | L18: primary | M18: Open map
A19: Cape Town | B19: Durbanville | C19: Hendrik Verwoerd Drive | D19: Uys Krige Drive | E19: Keep | H19: OpenStreetMap | I19: -33.88612 | J19: 18.61006 | K19: 78 | L19: tertiary | M19: Open map
A20: Cape Town | B20: Cape Town | C20: Coen Steytler Avenue | D20: Walter Sisulu Avenue | E20: Keep | H20: OpenStreetMap | I20: -33.91701 | J20: 18.4272 | K20: 13 | L20: tertiary | M20: Open map
A21: Cape Town | B21: Rosebank | C21: Ring Road | D21: Madiba Circle | E21: Check | G21: Campus/service road; confirm | H21: OpenStreetMap | I21: -33.95499 | J21: 18.46161 | K21: 4 | L21: service | M21: Open map
A22: Cape Town | B22: Cape Town | C22: Justice Street | D22: Rabbi Mirvish Avenue | E22: Check | G22: Short street; confirm with City of Cape Town | H22: OpenStreetMap | I22: -33.93695 | J22: 18.41923 | K22: 1 | L22: residential | M22: Open map
A23: Cape Town | B23: Cape Town | C23: Western Boulevard | D23: Beach Road | E23: Drop | G23: Mapping detail: only a short joining segment | H23: OpenStreetMap | I23: -33.9064 | J23: 18.39846 | K23: 2 | L23: primary | M23: Open map
A24: Cape Town | B24: Simon's Town | C24: Goede Gift Road | D24: Flagship Way | E24: Drop | G24: A flight of steps, not a street | H24: OpenStreetMap | I24: -34.19419 | J24: 18.43244 | K24: 1 | L24: steps | M24: Open map
A25: Cape Town | B25: Cape Town | C25: Western Boulevard | D25: Hans Strijdom Avenue | E25: Drop | G25: Mapping detail: only a short joining segment | H25: OpenStreetMap | I25: -33.91575 | J25: 18.42235 | K25: 2 | L25: primary | M25: Open map
A26: Cape Town | B26: Claremont | C26: Lansdowne Road | D26: Palmyra Road | E26: Drop | G26: Mapping detail: only a short joining segment | H26: OpenStreetMap | I26: -33.98269 | J26: 18.46791 | K26: 2 | L26: primary | M26: Open map
A27: Cape Town | B27: Durbanville | C27: Alexandra Street | D27: Protea Street | E27: Drop | G27: Small local change | H27: OpenStreetMap | I27: -33.89488 | J27: 18.62856 | K27: 1 | L27: residential | M27: Open map
A28: Cape Town | B28: Cape Town | C28: De Waal Drive Service Road | D28: Service Road | E28: Drop | G28: Service road, not a rename | H28: OpenStreetMap | I28: -33.93494 | J28: 18.43156 | K28: 1 | L28: residential | M28: Open map
A29: Cape Town | B29: Athlone | C29: Zone 5 Road | D29: Washington Drive | E29: Drop | G29: Township zone number replaced by a name | H29: OpenStreetMap | I29: -33.94602 | J29: 18.53375 | K29: 4 | L29: tertiary | M29: Open map
A30: Cape Town | B30: Athlone | C30: Zone 16 Road | D30: Washington Drive | E30: Drop | G30: Township zone number replaced by a name | H30: OpenStreetMap | I30: -33.94624 | J30: 18.53594 | K30: 1 | L30: tertiary | M30: Open map
A31: Durban (eThekwini) | B31: Durban | C31: Kensington Drive | D31: Adelaide Tambo Drive | E31: Keep | H31: OpenStreetMap | I31: -29.77512 | J31: 31.04417 | K31: 17 | L31: tertiary | M31: Open map
A32: Durban (eThekwini) | B32: Durban | C32: Smith Street | D32: Anton Lembede Street | E32: Keep | H32: OpenStreetMap | I32: -29.86159 | J32: 31.01056 | K32: 25 | L32: primary | M32: Open map
A33: Durban (eThekwini) | B33: Durban | C33: Old Fort Place | D33: Archie Gumede Place | E33: Keep | H33: OpenStreetMap | I33: -29.85072 | J33: 31.02471 | K33: 10 | L33: residential | M33: Open map
A34: Durban (eThekwini) | B34: Durban | C34: Victoria Street | D34: Bertha Mkhize Street | E34: Keep | H34: OpenStreetMap | I34: -29.8555 | J34: 31.02215 | K34: 6 | L34: tertiary | M34: Open map
A35: Durban (eThekwini) | B35: Durban | C35: Ordnance Road | D35: Bram Fischer Road | E35: Keep | H35: OpenStreetMap | I35: -29.85306 | J35: 31.02189 | K35: 9 | L35: trunk | M35: Open map
A36: Durban (eThekwini) | B36: Durban | C36: Beatrice Street | D36: Charlotte Maxeke Street | E36: Keep | H36: OpenStreetMap | I36: -29.85199 | J36: 31.01534 | K36: 13 | L36: tertiary | M36: Open map
A37: Durban (eThekwini) | B37: Berea | C37: Moore Road | D37: Che Guevara Road | E37: Keep | H37: OpenStreetMap | I37: -29.85539 | J37: 30.99818 | K37: 21 | L37: secondary | M37: Open map
A38: Durban (eThekwini) | B38: Berea | C38: North Coast Road | D38: Chris Hani Road | E38: Keep | H38: OpenStreetMap | I38: -29.80901 | J38: 31.01436 | K38: 114 | L38: primary | M38: Open map
A39: Durban (eThekwini) | B39: Ntuzuma | C39: KwaMashu Highway | D39: Curnick Ndlovu Highway | E39: Keep | H39: OpenStreetMap | I39: -29.75124 | J39: 31.01204 | K39: 42 | L39: primary | M39: Open map
A40: Durban (eThekwini) | B40: Durban | C40: Leopold Street | D40: David Webster Street | E40: Keep | H40: OpenStreetMap | I40: -29.85579 | J40: 31.01159 | K40: 14 | L40: tertiary | M40: Open map
...

Sheet Sources
A1: Source | B1: Link
A2: OpenStreetMap (old_name tags), via Overpass API, October 2026 | B2: https://www.openstreetmap.org/copyright
A3: SAnews: Tshwane Metro to proceed with street name changes (2012) | B3: https://www.sanews.gov.za/south-africa/tshwane-metro-proceed-street-name-changes
A4: The Heritage Portal: A Deeper Look at Johannesburg's New Street Names | B4: https://www.theheritageportal.co.za/article/deeper-look-johannesburgs-new-street-names
A5: BusinessTech: These 44 roads in Ekurhuleni are getting a name change (Oct 2021) | B5: https://businesstech.co.za/news/government/528874/these-44-roads-in-ekurhuleni-are-getting-a-name-change-what-you-need-to-know/
A6: IOL: Nine (Durban) street names to revert (Dec 2011) | B6: https://iol.co.za/news/south-africa/kwazulu-natal/2011-12-01-nine-street-names-to-revert/
A7: Supreme Court of Appeal judgment on the Durban renames (2011) | B7: https://lawlibrary.org.za/akn/za/judgment/zasca/2011/221
